
2023-09-14 13:30:59,840:__main__:
Filename: 20E545381v.2.pdf. Error occured in NLP flow module.
Traceback (most recent call last):
  File "/datadrive/EM_Product/ips/invoiceProduct_solution/apps/start_exacto.py", line 565, in __single_doc_process
    sta, dyn,config_id = drive_nlp_flow(os.path.splitext(document_path)[0], text_files_path, custom_extractor_obj, user=self.user_id, config=self.config_id)
  File "/datadrive/EM_Product/ips/invoiceProduct_solution/apps/exacto_extraction_flow.py", line 137, in drive_nlp_flow
    custom_field_dict = custom_extractor_obj.extract_custom_fields()
  File "/datadrive/EM_Product/ips/invoiceProduct_solution/apps/ExtractCustomFields/CustomFieldsExtractor.py", line 122, in extract_custom_fields
    for base_fname in self.pattern_files_dict:
  File "/datadrive/EM_Product/ips/invoiceProduct_solution/apps/ExtractCustomFields/CustomFieldsExtractor.py", line 45, in pattern_files_dict
    for file in os.listdir(self.pattern_folderpath):
FileNotFoundError: [Errno 2] No such file or directory: '/datadrive/EM_Product/eips_data/user_active_learning_data/CGI/560'
