
2022-04-19 12:31:15,524:__main__:
Filename: PNG_1.png. Error occured in NLP flow module.
Traceback (most recent call last):
  File "/drive/mnt/pradeep/invoiceProduct_solution/apps/start_exacto.py", line 541, in __single_doc_process
    sta, dyn,config_id = drive_nlp_flow(os.path.splitext(document_path)[0], text_files_path, custom_extractor_obj, user=self.user_id, config=self.config_id)
  File "/drive/mnt/pradeep/invoiceProduct_solution/apps/exacto_extraction_flow.py", line 131, in drive_nlp_flow
    custom_field_dict = custom_extractor_obj.extract_custom_fields()
  File "/drive/mnt/pradeep/invoiceProduct_solution/apps/ExtractCustomFields/CustomFieldsExtractor.py", line 119, in extract_custom_fields
    for base_fname in self.pattern_files_dict:
  File "/drive/mnt/pradeep/invoiceProduct_solution/apps/ExtractCustomFields/CustomFieldsExtractor.py", line 45, in pattern_files_dict
    for file in os.listdir(self.pattern_folderpath):
FileNotFoundError: [Errno 2] No such file or directory: '/drive/mnt/pradeep/eips/exacto/static/eips_data/user_active_learning_data/0ab40900/file api'

2022-04-19 12:32:56,157:__main__:
Filename: Invoice_2-4-2021.pdf. Error occured in ocr module.
Traceback (most recent call last):
  File "/drive/mnt/pradeep/invoiceProduct_solution/apps/start_exacto.py", line 533, in __single_doc_process
    ocr_success, text_files_path, phase, ocr_flag = drive_ocr_flow(esett.OCR_MODEL_PATHS, document_path, output_path)
  File "/drive/mnt/pradeep/invoiceProduct_solution/apps/exacto_extraction_flow.py", line 77, in drive_ocr_flow
    return ocr_success, text_files_path, phase, ocr_flag
UnboundLocalError: local variable 'text_files_path' referenced before assignment

2022-04-19 12:33:48,444:__main__:
Filename: Invoice_2-4-2021.pdf. Error occured in ocr module.
Traceback (most recent call last):
  File "/drive/mnt/pradeep/invoiceProduct_solution/apps/start_exacto.py", line 533, in __single_doc_process
    ocr_success, text_files_path, phase, ocr_flag = drive_ocr_flow(esett.OCR_MODEL_PATHS, document_path, output_path)
  File "/drive/mnt/pradeep/invoiceProduct_solution/apps/exacto_extraction_flow.py", line 77, in drive_ocr_flow
    return ocr_success, text_files_path, phase, ocr_flag
UnboundLocalError: local variable 'text_files_path' referenced before assignment

2022-04-19 12:34:40,051:__main__:
Filename: Invoice_2-4-2021.pdf. Error occured in ocr module.
Traceback (most recent call last):
  File "/drive/mnt/pradeep/invoiceProduct_solution/apps/start_exacto.py", line 533, in __single_doc_process
    ocr_success, text_files_path, phase, ocr_flag = drive_ocr_flow(esett.OCR_MODEL_PATHS, document_path, output_path)
  File "/drive/mnt/pradeep/invoiceProduct_solution/apps/exacto_extraction_flow.py", line 77, in drive_ocr_flow
    return ocr_success, text_files_path, phase, ocr_flag
UnboundLocalError: local variable 'text_files_path' referenced before assignment

2022-04-19 12:36:26,373:__main__:
Filename: Invoice_2-4-2021.pdf. Error occured in ocr module.
Traceback (most recent call last):
  File "/drive/mnt/pradeep/invoiceProduct_solution/apps/start_exacto.py", line 533, in __single_doc_process
    ocr_success, text_files_path, phase, ocr_flag = drive_ocr_flow(esett.OCR_MODEL_PATHS, document_path, output_path)
  File "/drive/mnt/pradeep/invoiceProduct_solution/apps/exacto_extraction_flow.py", line 77, in drive_ocr_flow
    return ocr_success, text_files_path, phase, ocr_flag
UnboundLocalError: local variable 'text_files_path' referenced before assignment
