
2022-03-31 09:35:24,830:__main__:
Filename: 1598459898413-Masked.pdf. Error occured in NLP flow module.
Traceback (most recent call last):
  File "/drive/mnt/pradeep/invoiceProduct_solution/apps/start_exacto.py", line 453, in __single_doc_process
    sta, dyn,config_id = drive_nlp_flow(os.path.splitext(document_path)[0], text_files_path, custom_extractor_obj, user=self.user_id, config=self.config_id)
  File "/drive/mnt/pradeep/invoiceProduct_solution/apps/exacto_extraction_flow.py", line 131, in drive_nlp_flow
    custom_field_dict = custom_extractor_obj.extract_custom_fields()
  File "/drive/mnt/pradeep/invoiceProduct_solution/apps/ExtractCustomFields/CustomFieldsExtractor.py", line 119, in extract_custom_fields
    for base_fname in self.pattern_files_dict:
  File "/drive/mnt/pradeep/invoiceProduct_solution/apps/ExtractCustomFields/CustomFieldsExtractor.py", line 45, in pattern_files_dict
    for file in os.listdir(self.pattern_folderpath):
FileNotFoundError: [Errno 2] No such file or directory: '/drive/mnt/pradeep/eips/exacto/static/eips_data/user_active_learning_data/fec5f1f9/table'

2022-03-31 09:35:28,664:__main__:
Filename: 1598459898413-Masked.pdf. Error occured in Business rules.
Traceback (most recent call last):
  File "/drive/mnt/pradeep/invoiceProduct_solution/apps/start_exacto.py", line 292, in get_file_and_process
    business_rule_final_dict = business_rules(business_rule_prev_dict['static'], business_user_id, config_id, company_code)
UnboundLocalError: local variable 'business_rule_prev_dict' referenced before assignment

2022-03-31 09:45:00,894:__main__:
Filename: 1598459898413-Masked.pdf. Error occured in NLP flow module.
Traceback (most recent call last):
  File "/drive/mnt/pradeep/invoiceProduct_solution/apps/start_exacto.py", line 460, in __single_doc_process
    sta, dyn,config_id = drive_nlp_flow(os.path.splitext(document_path)[0], text_files_path, custom_extractor_obj, user=self.user_id, config=self.config_id)
  File "/drive/mnt/pradeep/invoiceProduct_solution/apps/exacto_extraction_flow.py", line 131, in drive_nlp_flow
    custom_field_dict = custom_extractor_obj.extract_custom_fields()
  File "/drive/mnt/pradeep/invoiceProduct_solution/apps/ExtractCustomFields/CustomFieldsExtractor.py", line 119, in extract_custom_fields
    for base_fname in self.pattern_files_dict:
  File "/drive/mnt/pradeep/invoiceProduct_solution/apps/ExtractCustomFields/CustomFieldsExtractor.py", line 45, in pattern_files_dict
    for file in os.listdir(self.pattern_folderpath):
FileNotFoundError: [Errno 2] No such file or directory: '/drive/mnt/pradeep/eips/exacto/static/eips_data/user_active_learning_data/fec5f1f9/table'

2022-03-31 09:45:04,630:__main__:
Filename: 1598459898413-Masked.pdf. Error occured in Business rules.
Traceback (most recent call last):
  File "/drive/mnt/pradeep/invoiceProduct_solution/apps/start_exacto.py", line 299, in get_file_and_process
    business_rule_final_dict = business_rules(business_rule_prev_dict['static'], business_user_id, config_id, company_code)
UnboundLocalError: local variable 'business_rule_prev_dict' referenced before assignment
