
2023-09-06 04:35:38,698:__main__:
Filename: 20E541701v.1.pdf. Error occured in NLP flow module.
Traceback (most recent call last):
  File "/datadrive/EM_Product/ips/invoiceProduct_solution/apps/start_exacto.py", line 565, in __single_doc_process
    sta, dyn,config_id = drive_nlp_flow(os.path.splitext(document_path)[0], text_files_path, custom_extractor_obj, user=self.user_id, config=self.config_id)
  File "/datadrive/EM_Product/ips/invoiceProduct_solution/apps/exacto_extraction_flow.py", line 133, in drive_nlp_flow
    custom_field_dict = custom_extractor_obj.Nomination_field()
AttributeError: 'CustomFieldsExtractor' object has no attribute 'Nomination_field'

2023-09-06 05:03:17,531:__main__:
Filename: 20E541701v.1.pdf. Error occured in NLP flow module.
Traceback (most recent call last):
  File "/datadrive/EM_Product/ips/invoiceProduct_solution/apps/start_exacto.py", line 565, in __single_doc_process
    sta, dyn,config_id = drive_nlp_flow(os.path.splitext(document_path)[0], text_files_path, custom_extractor_obj, user=self.user_id, config=self.config_id)
  File "/datadrive/EM_Product/ips/invoiceProduct_solution/apps/exacto_extraction_flow.py", line 130, in drive_nlp_flow
    custom_field_dict = custom_extractor_obj.Nomination_field()
AttributeError: 'CustomFieldsExtractor' object has no attribute 'Nomination_field'

2023-09-06 06:36:15,516:__main__:
Filename: 20E541701v.1.pdf. Error occured in NLP flow module.
Traceback (most recent call last):
  File "/datadrive/EM_Product/ips/invoiceProduct_solution/apps/start_exacto.py", line 565, in __single_doc_process
    sta, dyn,config_id = drive_nlp_flow(os.path.splitext(document_path)[0], text_files_path, custom_extractor_obj, user=self.user_id, config=self.config_id)
  File "/datadrive/EM_Product/ips/invoiceProduct_solution/apps/exacto_extraction_flow.py", line 143, in drive_nlp_flow
    sta.update(custom_field_dict)
UnboundLocalError: local variable 'sta' referenced before assignment
